Workbook

Sheet % Progress
B2: Milestone | C2: Edition 66
C3: Total Slabs (includes mumty slabs, machine room slabs, mezzanine floors of penthouse) | D3: Achieved Slabs | E3: Achieved %
B4: Bulk Excavation | C4: _ | E4: 0.99
B5: Local Excavation | E5: 0.7
B6: PCC | C6: _ | E6: 0.7
B7: Tower Foundation/Raft | C7: 6 | D7: 6 | E7: 1
B8: Retaining Wall | C8: _ | E8: 0.3
B9: 3rd basement Floor Slab | C9: 6 | D9: 6 | E9: 1
B10: 2nd Basement Floor Slab | C10: 6 | D10: 6 | E10: 1
B11: 1st Basement Floor Slab | C11: 6 | D11: 6 | E11: 1
B12: Ground Slab | C12: 6 | D12: 6 | E12: 1
B13: 1st Floor Slab | C13: 6 | D13: 6 | E13: 1
B14: 2nd Floor Slab | C14: 6 | D14: 6 | E14: 1
B15: 3rd Floor Slab | C15: 6 | D15: 6 | E15: =D15/C15 -> 1
B16: 4th Floor Slab | C16: 6 | D16: 6 | E16: =D16/C16 -> 1
B17: 5th Floor Slab | C17: 6 | D17: 6 | E17: =D17/C17 -> 1
B18: 6th Floor Slab | C18: 6 | D18: 6 | E18: =D18/C18 -> 1
B19: 7th Floor Slab | C19: 6 | D19: 6 | E19: =D19/C19 -> 1
B20: 8th Floor Slab | C20: 6 | D20: 6 | E20: =D20/C20 -> 1
B21: 9th Floor Slab | C21: 6 | D21: 6 | E21: =D21/C21 -> 1
B22: 10th Floor Slab | C22: 6 | D22: 6 | E22: =D22/C22 -> 1
B23: 11th Floor Slab | C23: 6 | D23: 5 | E23: =D23/C23 -> 0.83333333
B24: 12th Floor Slab | C24: 6 | D24: 4 | E24: =D24/C24 -> 0.66666667
B25: 13th Floor Slab | C25: 6 | D25: 3 | E25: =D25/C25 -> 0.5
B26: 14th Floor Slab | C26: 6 | D26: 2 | E26: =D26/C26 -> 0.33333333
... B28: 16th Floor Slab | C28: 6 | D28: 1 | E28: =D28/C28 -> 0.16666667
B29: 17th Floor Slab | C29: 6
B30: 18th Floor Slab | C30: 6
B31: 19th Floor Slab | C31: 6
B32: 20th Floor Slab | C32: 6
B33: 21st Floor Slab | C33: 6
B34: 22nd Floor Slab | C34: 6
B35: 23rd Floor Slab | C35: 6
B36: 24th Floor Slab | C36: 6
B37: 25th Floor Slab | C37: 6
B38: 26th Floor Slab | C38: 6
B39: 27th Floor Slab | C39: 6
B40: 28th Floor Slab | C40: 6
... B56: Machine Room | C56: 6
B57: Total | C57: =SUM(C9:C56)+C7 -> 290 | D57: =SUM(D9:D56)+D7 -> 107

Sheet 01.06.26 Revised
B1: THE EDITION GROUP HOUSING SEC 66
B2: START DATE | C2: No. of days | D2: END DATE | G2: Structure Schedule_66
B3: 45511 | C3: 1285 | D3: =B3+C3 -> 46796 | G3: =C3/30.5 -> 42.131148
B5: Tower 6 | G5: Tower 5 | L5: Tower 1 | Q5: Tower 2 | V5: Tower 3 | AA5: Tower 4
C6: Actual /Anticipated Start | D6: No. of days | E6: Actual /Anticipated Finish | H6: Actual /Anticipated Start | I6: No. of days | J6: Actual /Anticipated Finish | M6: Actual /Anticipated Start | N6: No. of days | O6: Actual /Anticipated Finish | R6: Actual /Anticipated Start | S6: No. of days | T6: Actual /Anticipated Finish | W6: Actual /Anticipated Start | X6: No. of days | Y6: Actual /Anticipated Finish | AB6: Actual /Anticipated Start | AC6: No. of days | AD6: Actual /Anticipated Finish
B7: Surface Levelling & Dressing, Raft | C7: 45511 | D7: =E7-C7+1 -> 75 | E7: 45585 | G7: Surface Levelling & Dressing, Raft | H7: 45561 | I7: =J7-H7+1 -> 56 | J7: 45616 | L7: Surface Levelling & Dressing, Raft | M7: 45575 | N7: =O7-M7+1 -> 83 | O7: 45657 | Q7: Surface Levelling & Dressing, Raft | R7: 45582 | S7: =T7-R7+1 -> 90 | T7: 45671 | V7: Surface Levelling & Dressing, Raft | W7: 45589 | X7: =Y7-W7+1 -> 117 | Y7: 45705 | AA7: Surface Levelling & Dressing, Raft | AB7: 45596 | AC7: =AD7-AB7+1 -> 105 | AD7: 45700
B8: Basement 3 | C8: 45586 | D8: =E8-C8+1 -> 114 | E8: 45699 | G8: Basement 3 | H8: 45617 | I8: =J8-H8+1 -> 81 | J8: 45697 | L8: Basement 3 | M8: 45633 | N8: =O8-M8+1 -> 80 | O8: 45712 | Q8: Basement 3 | R8: 45642 | S8: =T8-R8+1 -> 80 | T8: 45721 | V8: Basement 3 | W8: 45706 | X8: =Y8-W8+1 -> 57 | Y8: 45762 | AA8: Basement 3 | AB8: 45701 | AC8: =AD8-AB8+1 -> 52 | AD8: 45752
B9: Basement 2 | C9: 45700 | D9: =E9-C9+1 -> 44 | E9: 45743 | G9: Basement 2 | H9: 45698 | I9: =J9-H9+1 -> 25 | J9: 45722 | L9: Basement 2 | M9: 45701 | N9: =O9-M9+1 -> 51 | O9: 45751 | Q9: Basement 2 | R9: 45730 | S9: =T9-R9+1 -> 37 | T9: 45766 | V9: Basement 2 | W9: 45739 | X9: =Y9-W9+1 -> 70 | Y9: 45808 | AA9: Basement 2 | AB9: 45752 | AC9: =AD9-AB9+1 -> 60 | AD9: 45811
B10: Basement 1 | C10: 45743 | D10: =E10-C10+1 -> 35 | E10: 45777 | G10: Basement 1 | H10: =J9 -> 45722 | I10: =J10-H10+1 -> 34 | J10: 45755 | L10: Basement 1 | M10: 45750 | N10: =O10-M10+1 -> 41 | O10: 45790 | Q10: Basement 1 | R10: 45766 | S10: =T10-R10+1 -> 44 | T10: 45809 | V10: Basement 1 | W10: =Y9 -> 45808 | X10: 51 | Y10: =X10+W10 -> 45859 | AA10: Basement 1 | AB10: =AD9 -> 45811 | AC10: 56 | AD10: =AC10+AB10 -> 45867
B11: Stilt Floor | C11: =E10 -> 45777 | D11: 78 | E11: =D11+C11 -> 45855 | G11: Stilt Floor | H11: 45756 | I11: =J11-H11+1 -> 45 | J11: 45800 | L11: Stilt Floor | M11: =O10 -> 45790 | N11: =58+19 -> 77 | O11: =N11+M11 -> 45867 | Q11: Stilt Floor | R11: =T10 -> 45809 | S11: 85 | T11: =S11+R11 -> 45894 | V11: Stilt Floor | W11: =Y10 -> 45859 | X11: 69 | Y11: =X11+W11 -> 45928 | AA11: Stilt Floor | AB11: =AD10 -> 45867 | AC11: 63 | AD11: =AC11+AB11 -> 45930
B12: 1st Floor | C12: =E11 -> 45855 | D12: 75 | E12: =D12+C12 -> 45930 | G12: 1st Floor | H12: =J11 -> 45800 | I12: 100 | J12: =H12+I12 -> 45900 | L12: 1st Floor | M12: =O11 -> 45867 | N12: 74 | O12: =N12+M12 -> 45941 | Q12: 1st Floor | R12: =T11 -> 45894 | S12: =52+12 -> 64 | T12: =S12+R12 -> 45958 | V12: 1st Floor | W12: =Y11 -> 45928 | X12: 65 | Y12: =X12+W12 -> 45993 | AA12: 1st Floor | AB12: =AD11 -> 45930 | AC12: 73 | AD12: =AC12+AB12 -> 46003
B13: 2nd Floor | C13: =E12 -> 45930 | D13: =32+15 -> 47 | E13: 45982 | G13: 2nd Floor | H13: =J12 -> 45900 | I13: =37+23 -> 60 | J13: 45934 | L13: 2nd Floor | M13: =O12 -> 45941 | N13: 43 | O13: =N13+M13 -> 45984 | Q13: 2nd Floor | R13: =T12 -> 45958 | S13: 35 | T13: =S13+R13 -> 45993 | V13: 2nd Floor | W13: =Y12 -> 45993 | X13: 40 | Y13: =X13+W13 -> 46033 | AA13: 2nd Floor | AB13: =AD12 -> 46003 | AC13: 29 | AD13: =AC13+AB13 -> 46032
B14: 3rd Floor | C14: =E13 -> 45982 | D14: 21 | E14: =D14+C14 -> 46003 | G14: 3rd Floor | H14: =J13 -> 45934 | I14: 24 | J14: =H14+I14 -> 45958 | L14: 3rd Floor | M14: =O13 -> 45984 | N14: 15 | O14: =N14+M14 -> 45999 | Q14: 3rd Floor | R14: =T13 -> 45993 | S14: 24 | T14: =S14+R14 -> 46017 | V14: 3rd Floor | W14: =Y13 -> 46033 | X14: 20 | Y14: =X14+W14 -> 46053 | AA14: 3rd Floor | AB14: =AD13 -> 46032 | AC14: 21 | AD14: =AC14+AB14 -> 46053
B15: 4th Floor | C15: =E14 -> 46003 | D15: 24 | E15: =D15+C15 -> 46027 | G15: 4th Floor | H15: =J14 -> 45958 | I15: 25 | J15: =H15+I15 -> 45983 | L15: 4th Floor | M15: =O14 -> 45999 | N15: 22 | O15: =N15+M15 -> 46021 | Q15: 4th Floor | R15: =T14 -> 46017 | S15: 14 | T15: =S15+R15 -> 46031 | V15: 4th Floor | W15: =Y14 -> 46053 | X15: 14 | Y15: =X15+W15 -> 46067 | AA15: 4th Floor | AB15: =AD14 -> 46053 | AC15: 15 | AD15: =AC15+AB15 -> 46068
B16: 5th Floor | C16: =E15 -> 46027 | D16: 14 | E16: =D16+C16 -> 46041 | G16: 5th Floor | H16: =J15 -> 45983 | I16: 20 | J16: =H16+I16 -> 46003 | L16: 5th Floor | M16: =O15 -> 46021 | N16: 18 | O16: =N16+M16 -> 46039 | Q16: 5th Floor | R16: =T15 -> 46031 | S16: 13 | T16: =S16+R16 -> 46044 | V16: 5th Floor | W16: =Y15 -> 46067 | X16: 14 | Y16: =X16+W16 -> 46081 | AA16: 5th Floor | AB16: =AD15 -> 46068 | AC16: 13 | AD16: =AC16+AB16 -> 46081
B17: 6th Floor | C17: =E16 -> 46041 | D17: 12 | E17: =D17+C17 -> 46053 | G17: 6th Floor | H17: =J16 -> 46003 | I17: 22 | J17: =H17+I17 -> 46025 | L17: 6th Floor | M17: =O16 -> 46039 | N17: 14 | O17: =N17+M17 -> 46053 | Q17: 6th Floor | R17: =T16 -> 46044 | S17: 14 | T17: =S17+R17 -> 46058 | V17: 6th Floor | W17: =Y16 -> 46081 | X17: 22 | Y17: =X17+W17 -> 46103 | AA17: 6th Floor | AB17: =AD16 -> 46081 | AC17: 18 | AD17: =AC17+AB17 -> 46099
B18: 7th Floor | C18: =E17 -> 46053 | D18: 14 | E18: =D18+C18 -> 46067 | G18: 7th Floor | H18: =J17 -> 46025 | I18: 14 | J18: =H18+I18 -> 46039 | L18: 7th Floor | M18: =O17 -> 46053 | N18: 13 | O18: =N18+M18 -> 46066 | Q18: 7th Floor | R18: =T17 -> 46058 | S18: 15 | T18: =S18+R18 -> 46073 | V18: 7th Floor | W18: =Y17 -> 46103 | X18: 14 | Y18: =X18+W18 -> 46117 | AA18: 7th Floor | AB18: =AD17 -> 46099 | AC18: 13 | AD18: =AC18+AB18 -> 46112
B19: 8th Floor | C19: =E18 -> 46067 | D19: 12 | E19: =D19+C19 -> 46079 | G19: 8th Floor | H19: =J18 -> 46039 | I19: 14 | J19: =H19+I19 -> 46053 | L19: 8th Floor | M19: =O18 -> 46066 | N19: 15 | O19: =N19+M19 -> 46081 | Q19: 8th Floor | R19: =T18 -> 46073 | S19: 18 | T19: =S19+R19 -> 46091 | V19: 8th Floor | W19: =Y18 -> 46117 | X19: 15 | Y19: =X19+W19 -> 46132 | AA19: 8th Floor | AB19: =AD18 -> 46112 | AC19: 15 | AD19: =AC19+AB19 -> 46127
B20: 9th Floor | C20: =E19 -> 46079 | D20: 13 | E20: =D20+C20 -> 46092 | G20: 9th Floor | H20: =J19 -> 46053 | I20: 13 | J20: =H20+I20 -> 46066 | L20: 9th Floor | M20: =O19 -> 46081 | N20: 19 | O20: =N20+M20 -> 46100 | Q20: 9th Floor | R20: =T19 -> 46091 | S20: 17 | T20: =S20+R20 -> 46108 | V20: 9th Floor | W20: =Y19 -> 46132 | X20: 13 | Y20: =X20+W20 -> 46145 | AA20: 9th Floor | AB20: =AD19 -> 46127 | AC20: 13 | AD20: =AC20+AB20 -> 46140
B21: 10th Floor | C21: =E20 -> 46092 | D21: 11 | E21: =D21+C21 -> 46103 | G21: 10th Floor | H21: =J20 -> 46066 | I21: 13 | J21: =H21+I21 -> 46079 | L21: 10th Floor | M21: =O20 -> 46100 | N21: 12 | O21: =N21+M21 -> 46112 | Q21: 10th Floor | R21: =T20 -> 46108 | S21: 17 | T21: =S21+R21 -> 46125 | V21: 10th Floor | W21: =Y20 -> 46145 | X21: 28 | Y21: =X21+W21 -> 46173 | AA21: 10th Floor | AB21: =AD20 -> 46140 | AC21: 13 | AD21: =AC21+AB21 -> 46153
B22: 11th Floor | C22: =E21 -> 46103 | D22: 9 | E22: =D22+C22 -> 46112 | G22: 11th Floor | H22: =J21 -> 46079 | I22: 15 | J22: =H22+I22 -> 46094 | L22: 11th Floor | M22: =O21 -> 46112 | N22: 20 | O22: =N22+M22 -> 46132 | Q22: 11th Floor | R22: =T21 -> 46125 | S22: 17 | T22: =S22+R22 -> 46142 | V22: 11th Floor | W22: =Y21 -> 46173 | X22: 12 | Y22: =X22+W22 -> 46185 | AA22: 11th Floor | AB22: =AD21 -> 46153 | AC22: 20 | AD22: =AC22+AB22 -> 46173
B23: 12th Floor | C23: =E22 -> 46112 | D23: 13 | E23: =D23+C23 -> 46125 | G23: 12th Floor | H23: =J22 -> 46094 | I23: 15 | J23: =H23+I23 -> 46109 | L23: 12th Floor | M23: =O22 -> 46132 | N23: 12 | O23: =N23+M23 -> 46144 | Q23: 12th Floor | R23: =T22 -> 46142 | S23: 24 | T23: =S23+R23 -> 46166 | V23: 12th Floor | W23: =Y22 -> 46185 | X23: 12 | Y23: =X23+W23 -> 46197 | AA23: 12th Floor | AB23: =AD22 -> 46173 | AC23: =X23 -> 12 | AD23: =AC23+AB23 -> 46185
B24: 13th Floor | C24: =E23 -> 46125 | D24: 12 | E24: =D24+C24 -> 46137 | G24: 13th Floor | H24: =J23 -> 46109 | I24: 13 | J24: =H24+I24 -> 46122 | L24: 13th Floor | M24: =O23 -> 46144 | N24: 29 | O24: =N24+M24 -> 46173 | Q24: 13th Floor | R24: =T23 -> 46166 | S24: 13 | T24: =S24+R24 -> 46179 | V24: 13th Floor | W24: =Y23 -> 46197 | X24: 12 | Y24: =X24+W24 -> 46209 | AA24: 13th Floor | AB24: =AD23 -> 46185 | AC24: =X24 -> 12 | AD24: =AC24+AB24 -> 46197
B25: 14th Floor | C25: =E24 -> 46137 | D25: 15 | E25: =D25+C25 -> 46152 | G25: 14th Floor | H25: =J24 -> 46122 | I25: 11 | J25: =H25+I25 -> 46133 | L25: 14th Floor | M25: =O24 -> 46173 | N25: 13 | O25: =N25+M25 -> 46186 | Q25: 14th Floor | R25: =T24 -> 46179 | S25: 12 | T25: =S25+R25 -> 46191 | V25: 14th Floor | W25: =Y24 -> 46209 | X25: 12 | Y25: =X25+W25 -> 46221 | AA25: 14th Floor | AB25: =AD24 -> 46197 | AC25: =X25 -> 12 | AD25: =AC25+AB25 -> 46209
B26: 15th Floor | C26: =E25 -> 46152 | D26: 18 | E26: =D26+C26 -> 46170 | G26: 15th Floor | H26: =J25 -> 46133 | I26: 16 | J26: =H26+I26 -> 46149 | L26: 15th Floor | M26: =O25 -> 46186 | N26: 12 | O26: =N26+M26 -> 46198 | Q26: 15th Floor | R26: =T25 -> 46191 | S26: =N26 -> 12 | T26: =S26+R26 -> 46203 | V26: 15th Floor | W26: =Y25 -> 46221 | X26: =S26 -> 12 | Y26: =X26+W26 -> 46233 | AA26: 15th Floor | AB26: =AD25 -> 46209 | AC26: =X26 -> 12 | AD26: =AC26+AB26 -> 46221
B27: 16th Floor | C27: =E26 -> 46170 | D27: 13 | E27: =D27+C27 -> 46183 | G27: 16th Floor | H27: =J26 -> 46149 | I27: 17 | J27: =H27+I27 -> 46166 | L27: 16th Floor | M27: =O26 -> 46198 | N27: 12 | O27: =N27+M27 -> 46210 | Q27: 16th Floor | R27: =T26 -> 46203 | S27: =N27 -> 12 | T27: =S27+R27 -> 46215 | V27: 16th Floor | W27: =Y26 -> 46233 | X27: 12 | Y27: =X27+W27 -> 46245 | AA27: 16th Floor | AB27: =AD26 -> 46221 | AC27: =X27 -> 12 | AD27: =AC27+AB27 -> 46233
B28: 17th Floor | C28: =E27 -> 46183 | D28: 13 | E28: =D28+C28 -> 46196 | G28: 17th Floor | H28: =J27 -> 46166 | I28: =D28 -> 13 | J28: =H28+I28 -> 46179 | L28: 17th Floor | M28: =O27 -> 46210 | N28: 12 | O28: =N28+M28 -> 46222 | Q28: 17th Floor | R28: =T27 -> 46215 | S28: =N28 -> 12 | T28: =S28+R28 -> 46227 | V28: 17th Floor | W28: =Y27 -> 46245 | X28: 12 | Y28: =X28+W28 -> 46257 | AA28: 17th Floor | AB28: =AD27 -> 46233 | AC28: =X28 -> 12 | AD28: =AC28+AB28 -> 46245
B29: 18th Floor | C29: =E28 -> 46196 | D29: 14 | E29: =D29+C29 -> 46210 | G29: 18th Floor | H29: =J28 -> 46179 | I29: =D29 -> 14 | J29: =H29+I29 -> 46193 | L29: 18th Floor | M29: =O28 -> 46222 | N29: 14 | O29: =N29+M29 -> 46236 | Q29: 18th Floor | R29: =T28 -> 46227 | S29: 12 | T29: =S29+R29 -> 46239 | V29: 18th Floor | W29: =Y28 -> 46257 | X29: 12 | Y29: =X29+W29 -> 46269 | AA29: 18th Floor | AB29: =AD28 -> 46245 | AC29: =X29 -> 12 | AD29: =AC29+AB29 -> 46257
B30: 19th Floor | C30: =E29 -> 46210 | D30: 13 | E30: =D30+C30 -> 46223 | G30: 19th Floor | H30: =J29 -> 46193 | I30: =D30 -> 13 | J30: =H30+I30 -> 46206 | L30: 19th Floor | M30: =O29 -> 46236 | N30: 12 | O30: =N30+M30 -> 46248 | Q30: 19th Floor | R30: =T29 -> 46239 | S30: =N30 -> 12 | T30: =S30+R30 -> 46251 | V30: 19th Floor | W30: =Y29 -> 46269 | X30: 12 | Y30: =X30+W30 -> 46281 | AA30: 19th Floor | AB30: =AD29 -> 46257 | AC30: =X30 -> 12 | AD30: =AC30+AB30 -> 46269
B31: 20th Floor | C31: =E30 -> 46223 | D31: 13 | E31: =D31+C31 -> 46236 | G31: 20th Floor | H31: =J30 -> 46206 | I31: 14 | J31: =H31+I31 -> 46220 | L31: 20th Floor | M31: =O30 -> 46248 | N31: 12 | O31: =N31+M31 -> 46260 | Q31: 20th Floor | R31: =T30 -> 46251 | S31: =N31 -> 12 | T31: =S31+R31 -> 46263 | V31: 20th Floor | W31: =Y30 -> 46281 | X31: 12 | Y31: =X31+W31 -> 46293 | AA31: 20th Floor | AB31: =AD30 -> 46269 | AC31: =X31 -> 12 | AD31: =AC31+AB31 -> 46281
B32: 21st Floor | C32: =E31 -> 46236 | D32: 13 | E32: =D32+C32 -> 46249 | G32: 21st Floor | H32: =J31 -> 46220 | I32: 14 | J32: =H32+I32 -> 46234 | L32: 21st Floor | M32: =O31 -> 46260 | N32: 12 | O32: =N32+M32 -> 46272 | Q32: 21st Floor | R32: =T31 -> 46263 | S32: =N32 -> 12 | T32: =S32+R32 -> 46275 | V32: 21st Floor | W32: =Y31 -> 46293 | X32: 11 | Y32: =X32+W32 -> 46304 | AA32: 21st Floor | AB32: =AD31 -> 46281 | AC32: 12 | AD32: =AC32+AB32 -> 46293
B33: 22nd Floor | C33: =E32 -> 46249 | D33: 13 | E33: =D33+C33 -> 46262 | G33: 22nd Floor | H33: =J32 -> 46234 | I33: 14 | J33: =H33+I33 -> 46248 | L33: 22nd Floor | M33: =O32 -> 46272 | N33: 12 | O33: =N33+M33 -> 46284 | Q33: 22nd Floor | R33: =T32 -> 46275 | S33: 12 | T33: =S33+R33 -> 46287 | V33: 22nd Floor | W33: =Y32 -> 46304 | X33: 11 | Y33: =X33+W33 -> 46315 | AA33: 22nd Floor | AB33: =AD32 -> 46293 | AC33: 12 | AD33: =AC33+AB33 -> 46305
B34: 23rd Floor | C34: =E33 -> 46262 | D34: 13 | E34: =D34+C34 -> 46275 | G34: 23rd Floor | H34: =J33 -> 46248 | I34: 14 | J34: =H34+I34 -> 46262 | L34: 23rd Floor | M34: =O33 -> 46284 | N34: 12 | O34: =N34+M34 -> 46296 | Q34: 23rd Floor | R34: =T33 -> 46287 | S34: 12 | T34: =S34+R34 -> 46299 | V34: 23rd Floor | W34: =Y33 -> 46315 | X34: 11 | Y34: =X34+W34 -> 46326 | AA34: 23rd Floor | AB34: =AD33 -> 46305 | AC34: =X34 -> 11 | AD34: =AC34+AB34 -> 46316
B35: 24th Floor | C35: =E34 -> 46275 | D35: 13 | E35: =D35+C35 -> 46288 | G35: 24th Floor | H35: =J34 -> 46262 | I35: 14 | J35: =H35+I35 -> 46276 | L35: 24th Floor | M35: =O34 -> 46296 | N35: 12 | O35: =N35+M35 -> 46308 | Q35: 24th Floor | R35: =T34 -> 46299 | S35: 12 | T35: =S35+R35 -> 46311 | V35: 24th Floor | W35: =Y34 -> 46326 | X35: 11 | Y35: =X35+W35 -> 46337 | AA35: 24th Floor | AB35: =AD34 -> 46316 | AC35: =X35 -> 11 | AD35: =AC35+AB35 -> 46327
B36: 25th Floor | C36: =E35 -> 46288 | D36: 13 | E36: =D36+C36 -> 46301 | G36: 25th Floor | H36: =J35 -> 46276 | I36: 14 | J36: =H36+I36 -> 46290 | L36: 25th Floor | M36: =O35 -> 46308 | N36: 12 | O36: =N36+M36 -> 46320 | Q36: 25th Floor | R36: =T35 -> 46311 | S36: 12 | T36: =S36+R36 -> 46323 | V36: 25th Floor | W36: =Y35 -> 46337 | X36: 12 | Y36: =X36+W36 -> 46349 | AA36: 25th Floor | AB36: =AD35 -> 46327 | AC36: =X36 -> 12 | AD36: =AC36+AB36 -> 46339
B37: 26th Floor | C37: =E36 -> 46301 | D37: 13 | E37: =D37+C37 -> 46314 | G37: 26th Floor | H37: =J36 -> 46290 | I37: 14 | J37: =H37+I37 -> 46304 | L37: 26th Floor | M37: =O36 -> 46320 | N37: 12 | O37: =N37+M37 -> 46332 | Q37: 26th Floor | R37: =T36 -> 46323 | S37: 12 | T37: =S37+R37 -> 46335 | V37: 26th Floor | W37: =Y36 -> 46349 | X37: 11 | Y37: =X37+W37 -> 46360 | AA37: 26th Floor | AB37: =AD36 -> 46339 | AC37: =X37 -> 11 | AD37: =AC37+AB37 -> 46350
B38: 27th Floor | C38: =E37 -> 46314 | D38: 15 | E38: =D38+C38 -> 46329 | G38: 27th Floor | H38: =J37 -> 46304 | I38: =D38 -> 15 | J38: =H38+I38 -> 46319 | L38: 27th Floor | M38: =O37 -> 46332 | N38: 13 | O38: =N38+M38 -> 46345 | Q38: 27th Floor | R38: =T37 -> 46335 | S38: 12 | T38: =S38+R38 -> 46347 | V38: 27th Floor | W38: =Y37 -> 46360 | X38: 11 | Y38: =X38+W38 -> 46371 | AA38: 27th Floor | AB38: =AD37 -> 46350 | AC38: =X38 -> 11 | AD38: =AC38+AB38 -> 46361
B39: 28th Floor | C39: =E38 -> 46329 | D39: 13 | E39: =D39+C39 -> 46342 | G39: 28th Floor | H39: =J38 -> 46319 | I39: 14 | J39: =H39+I39 -> 46333 | L39: 28th Floor | M39: =O38 -> 46345 | N39: 12 | O39: =N39+M39 -> 46357 | Q39: 28th Floor | R39: =T38 -> 46347 | S39: 12 | T39: =S39+R39 -> 46359 | V39: 28th Floor | W39: =Y38 -> 46371 | X39: 11 | Y39: =X39+W39 -> 46382 | AA39: 28th Floor | AB39: =AD38 -> 46361 | AC39: =X39 -> 11 | AD39: =AC39+AB39 -> 46372
B40: 29th Floor | C40: =E39 -> 46342 | D40: 12 | E40: =D40+C40 -> 46354 | G40: 29th Floor | H40: =J39 -> 46333 | I40: 13 | J40: =H40+I40 -> 46346 | L40: 29th Floor | M40: =O39 -> 46357 | N40: 12 | O40: =N40+M40 -> 46369 | Q40: 29th Floor | R40: =T39 -> 46359 | S40: 12 | T40: =S40+R40 -> 46371 | V40: 29th Floor | W40: =Y39 -> 46382 | X40: 11 | Y40: =X40+W40 -> 46393 | AA40: 29th Floor | AB40: =AD39 -> 46372 | AC40: =X40 -> 11 | AD40: =AC40+AB40 -> 46383
B41: 30th Floor | C41: =E40 -> 46354 | D41: 12 | E41: =D41+C41 -> 46366 | G41: 30th Floor | H41: =J40 -> 46346 | I41: 13 | J41: =H41+I41 -> 46359 | L41: 30th Floor | M41: =O40 -> 46369 | N41: 12 | O41: =N41+M41 -> 46381 | Q41: 30th Floor | R41: =T40 -> 46371 | S41: =N41 -> 12 | T41: =S41+R41 -> 46383 | V41: 30th Floor | W41: =Y40 -> 46393 | X41: 11 | Y41: =X41+W41 -> 46404 | AA41: 30th Floor | AB41: =AD40 -> 46383 | AC41: =X41 -> 11 | AD41: =AC41+AB41 -> 46394
...

Sheet Revised CRM milestones
B3: Milestone | C3: Tower 1 | D3: Tower 2 | E3: Tower 3 | F3: Tower 4 | G3: Tower 5 | H3: Tower 6
B4: On Application of Booking | C4: As per customer booking
B5: Within 30 days of Booking less : Booking amount | C5: As per customer booking
B6: Start of Excavation | C6: 45323 | D6: 45323 | E6: 45323 | F6: 45323 | G6: 45292 | H6: 45292
B7: On Completion of Ground floor Slab | C7: 45839 | D7: 45839 | E7: 45839 | F7: 45839 | G7: 45778 | H7: 45778
D8: 45870 | E8: 45901 | F8: 45901 | H8: 45839
B9: On Completion of 5th floor Slab | C9: 45962 | D9: 45962 | E9: 45992 | F9: 45992 | G9: 45931 | H9: 45931
C10: 46023 | D10: 46054 | E10: 46082 | F10: 46082 | G10: 46357 | H10: 46023
B11: On Completion of 15th floor Slab | C11: 46113 | D11: 46143 | E11: 46143 | F11: 46143 | G11: 46082 | H11: 46082
C12: ='01.06.26 Revised'!O26 -> 46198 | D12: ='01.06.26 Revised'!T26 -> 46203 | E12: ='01.06.26 Revised'!Y26 -> 46233 | F12: ='01.06.26 Revised'!AD26 -> 46221 | G12: ='01.06.26 Revised'!J26 -> 46149 | H12: ='01.06.26 Revised'!E26 -> 46170
B13: On Completion of 25th floor Slab | C13: 46235 | D13: 46235 | E13: 46266 | F13: 46266 | G13: 46204 | H13: 46204
C14: ='01.06.26 Revised'!O36 -> 46320 | D14: ='01.06.26 Revised'!T36 -> 46323 | E14: 46357 | F14: =E14 -> 46357 | G14: 46296 | H14: 46327
B15: Completion Till Below Penthouse
C16: ='01.06.26 Revised'!O49 -> 46477 | D16: ='01.06.26 Revised'!T49 -> 46477 | E16: ='01.06.26 Revised'!Y49 -> 46492 | F16: ='01.06.26 Revised'!AD49 -> 46484 | G16: ='01.06.26 Revised'!E50 -> 46477 | H16: ='01.06.26 Revised'!J50 -> 46477
B17: On Completion of Structure | C17: 46447 | D17: 46447 | E17: 46447 | F17: 46447 | G17: 46419 | H17: 46419
C18: ='01.06.26 Revised'!O52 -> 46537 | D18: ='01.06.26 Revised'!T52 -> 46537 | E18: ='01.06.26 Revised'!Y52 -> 46587 | F18: ='01.06.26 Revised'!AD52 -> 46579 | G18: ='01.06.26 Revised'!E53 -> 46537 | H18: ='01.06.26 Revised'!J53 -> 46537
B19: On Application of Occupation Certificate | C19: 46722
C20: ='01.06.26 Revised'!E57 -> 46903
B21: Projected Completion | C21: ='01.06.26 Revised'!E58 -> 0
B22: On Offer of Possession | C22: After OC
